Workbook

Sheet Cover_Assumptions
A1: HP Print Franchise Portfolio - Cover Assumptions
A3: Discount Rate & Horizon
A4: Discount Rate (WACC) | B4: 0.08 | C4: Source: Midpoint of Alpha Spread (7.47%) and valueinvesting.io (9.0%) HPQ-specific WACC estimates
A5: Horizon Start (FY) | B5: 2027
A6: Horizon End (FY) | B6: 2031
A7: Horizon Length (Years) | B7: =B6-B5+1 -> 5
A9: Real Anchoring Data (HP FY25 10-K & Earnings Releases)
A10: Total HP Net Revenue, FY25 ($B) | B10: 55.3 | C10: Source: HP Inc. FY25 10-K / Q4 FY25 Earnings Release, SEC EDGAR
A11: Printing Segment Net Revenue, FY25 ($B) | B11: 16.8 | C11: Source: Sum of Q1-Q4 FY25 8-K earnings releases (SEC EDGAR)
A12: Printing Segment Operating Margin, FY25 (blended) | B12: =AVERAGE(19%,19.5%,17.3%,18.9%) -> 0.18675 | C12: Source: Q1-Q4 FY25 earnings releases; true 4-quarter average, not a single-quarter proxy
A13: Supplies Revenue Decline, FY25 (YoY) | B13: -0.034 | C13: Source: HP FY25 10-K - "decline in the installed base and usage"
A14: Hardware Unit Volume Decline, FY25 (YoY) | B14: -0.042 | C14: Source: HP FY25 10-K
A15: Hardware ASP Decline, FY25 (YoY) | B15: -0.015 | C15: Source: HP FY25 10-K
A17: Option A - New Printer Generation Launch: Locked Assumptions
A18: Hardware Margin | B18: 0.04 | C18: Derived: back-solved from FY25 blended Printing margin (18.7%) and est. hardware ~35% of segment revenue. Not an HP-disclosed figure.
A19: Supplies Margin | B19: 0.28 | C19: Derived alongside hardware margin to reconcile blended 18.7% average. Not an HP-disclosed figure.
A20: NPI Launch Cost - Lean ($M) | B20: 150
A21: NPI Launch Cost - Base ($M) | B21: 200
A22: NPI Launch Cost - Ambitious ($M) | B22: 300 | C22: Bounded against HP's disclosed FY25 total company R&D expense ($1.6B; MacroTrends/10-K). Not a bottom-up or sourced figure - the single most estimated most estimated number in Option A.
A23: Aftermarket Recapture Premium - Downside | B23: 0.015
A24: Aftermarket Recapture Premium - Base | B24: 0.035
A25: Aftermarket Recapture Premium - Upside | B25: 0.065 | C25: Scaled off the real -3.4% FY25 Supplies decline (only available reference point). Softest assumption in Option A - no disclosed decay-curve data.
A26: Estimated Hardware % of Printing Segment Revenue | B26: 0.35 | C26: Older public estimate cited in press coverage - not a disclosed HP figure; same derivation used for the 4%/28% margin split
A27: Estimated Hardware Revenue, FY25 ($B) | B27: =B11*B26 -> 5.88
A28: Scope limitation: Option A's economics are presented at full Printing-segment scale (all product lines, all generations, consumer and commercial combined). A real single-generation launch decision represents some fraction of this that HP does not publicly disclose and this model does not estimate. Figures here should be read as a ceiling case for a segment-wide refresh posture, not the literal economics of one product launch. Option B is scoped to the global consumer/home segment specifically.
A30: Option B - Instant Ink Subscription Accelaration: Locked Assumptions
A31: Subscriber Base, FY24 (millions) | B31: 13 | C31: Source: HP mgmt (Lores), Morgan Stanley TMT Conf., Mar 2024 - last explicit disclosed figure
A32: Organic Growth Rate, FY27+ (Do-Nothing) | B32: 0.07 | C32: Derived from historical CAGR deceleration: 21%/yr (2020-22) -> 9%/yr (2022-24) -> ~7%/yr projected
A33: CAC per Incremental Subscriber - Lean | B33: 20 | C33: Grounded in the model's own derived ARPU (~$79/subscriber/yr, from verified FY27 subscription revenue ÷ projected subscriber base) — CAC bracket set around half a year's ARPU at Base, standard subscription-business framing. Not an external estimate.
A34: CAC per Incremental Subscriber - Base | B34: 40
A35: CAC per Incremental Subscriber - Ambitious | B35: 60
A36: Growth Accelaration - Downside (pts) | B36: 0.02
A37: Growth Accelaration - Base (pts) | B37: 0.04
A38: Growth Accelaration - Upside (pts) | B38: 0.08 | C38: Anchored to real historical CAGR; upside deliberately kept below HP's own +25% FY26 target (investor guidance, not base-case-acheivable)
A39: Subscription Share of Supplies Revenue | B39: 0.1 | C39: Triangulated: (a) Instant Ink pricing $5-8/mo × 13M subs × 12mo ≈ $780M-1.25B, ~7-12% of $10.9B Supplies base; (b) 10% sits mid-range. Not an HP-disclosed figure.
A40: Non-Subscription Residual Decline Rate | B40: =(((1+Cover_Assumptions!$B$13)-Cover_Assumptions!$B$39*(1+Cover_Assumptions!$B$32))/(1-Cover_Assumptions!$B$39))-1 -> -0.045555556 | C40: Back-solved so the blend of subscription growth + non-subscription decline reconciles to the real -3.4% aggregate Supplies decline. Derived, not a new judgment call — same method as the 28% supplies margin derivation.
A41: Subscriber Base, FY26E (bridged, millions) | B41: =B31*(1+B32)^2 -> 14.8837
A42: Note: subscriber LTV lift (per HP's disclosed commentary — moving a customer to a "digital relationship" was stated to lift lifetime value 20%+, with "all-in plan" conversions specifically cited at 50%+) is not modeled as a separate revenue driver here. It's deliberately excluded to avoid conflating a volume mechanic (growth acceleration, modeled) with a value-per-conversion mechanic (LTV, not modeled) — the two are separate claims from separate evidence, and combining them without full rigor would overstate precision. Actual revenue uplift could be meaningfully higher than shown here as a result.
A44: Combined Scenario - Locked Assumptions
A45: New-Generation Subscriber Attach Rate | B45: 0.15 | C45: Softest assumption in the model — two steps removed from any disclosed figure. Loosely bounded by the real 60% HP+-eligible-shipment figure (2023) as a ceiling on connectivity-capable buyers; not derived from a disclosed conversion rate.
...

Sheet Option_A
A1: Option A - New Printer Generation Launch
A2: Recapture Premium Scenario: | B2: Base | C2: =CHOOSE(MATCH($B$2,{"Downside","Base","Upside"},0),Cover_Assumptions!$B$23,Cover_Assumptions!$B$24,Cover_Assumptions!$B$25) -> 0.035
A3: NPI Cost Scenario: | B3: Base | C3: =CHOOSE(MATCH($B$3,{"Lean","Base","Ambitious"},0),Cover_Assumptions!$B$20,Cover_Assumptions!$B$21,Cover_Assumptions!$B$22) -> 200
A4: Do-Nothing Case
B5: FY27 | C5: FY28 | D5: FY29 | E5: FY30 | F5: FY31
A6: Hardware Units (index, FY26=100) | B6: =100*(1+Cover_Assumptions!$B$14) -> 95.8 | C6: =B6*(1+Cover_Assumptions!$B$14) -> 91.7764 | D6: =C6*(1+Cover_Assumptions!$B$14) -> 87.921791 | E6: =D6*(1+Cover_Assumptions!$B$14) -> 84.229076 | F6: =E6*(1+Cover_Assumptions!$B$14) -> 80.691455
A7: Hardware ASP (index, FY26=100) | B7: =100*(1+Cover_Assumptions!$B$15) -> 98.5 | C7: =B7*(1+Cover_Assumptions!$B$15) -> 97.0225 | D7: =C7*(1+Cover_Assumptions!$B$15) -> 95.567162 | E7: =D7*(1+Cover_Assumptions!$B$15) -> 94.133655 | F7: =E7*(1+Cover_Assumptions!$B$15) -> 92.72165
A8: Hardware Revenue (index) | B8: =B6*B7/100 -> 94.363 | C8: =C6*C7/100 -> 89.043758 | D8: =D6*D7/100 -> 84.024361 | E8: =E6*E7/100 -> 79.287908 | F8: =F6*F7/100 -> 74.818448
A10: Hardware Revenue ($M) | B10: =Cover_Assumptions!$B$27*1000*(1+Cover_Assumptions!$B$14)*(1+Cover_Assumptions!$B$15)*(B8/100) -> 5235.773 | C10: =Cover_Assumptions!$B$27*1000*(1+Cover_Assumptions!$B$14)*(1+Cover_Assumptions!$B$15)*(C8/100) -> 4940.6324 | D10: =Cover_Assumptions!$B$27*1000*(1+Cover_Assumptions!$B$14)*(1+Cover_Assumptions!$B$15)*(D8/100) -> 4662.129 | E10: =Cover_Assumptions!$B$27*1000*(1+Cover_Assumptions!$B$14)*(1+Cover_Assumptions!$B$15)*(E8/100) -> 4399.3248 | F10: =Cover_Assumptions!$B$27*1000*(1+Cover_Assumptions!$B$14)*(1+Cover_Assumptions!$B$15)*(F8/100) -> 4151.3348
A12: Supplies Capture Rate (index, FY26=100) | B12: =100*(1+Cover_Assumptions!$B$13) -> 96.6 | C12: =B12*(1+Cover_Assumptions!$B$13) -> 93.3156 | D12: =C12*(1+Cover_Assumptions!$B$13) -> 90.14287 | E12: =D12*(1+Cover_Assumptions!$B$13) -> 87.078012 | F12: =E12*(1+Cover_Assumptions!$B$13) -> 84.11736
A14: Supplies Revenue ($M) | B14: =(Cover_Assumptions!$B$11*1000-Cover_Assumptions!$B$27*1000)*(1+Cover_Assumptions!$B$13)*(B12/100) -> 10190.064 | C14: =(Cover_Assumptions!$B$11*1000-Cover_Assumptions!$B$27*1000)*(1+Cover_Assumptions!$B$13)*(C12/100) -> 9843.6014 | D14: =(Cover_Assumptions!$B$11*1000-Cover_Assumptions!$B$27*1000)*(1+Cover_Assumptions!$B$13)*(D12/100) -> 9508.9189 | E14: =(Cover_Assumptions!$B$11*1000-Cover_Assumptions!$B$27*1000)*(1+Cover_Assumptions!$B$13)*(E12/100) -> 9185.6157 | F14: =(Cover_Assumptions!$B$11*1000-Cover_Assumptions!$B$27*1000)*(1+Cover_Assumptions!$B$13)*(F12/100) -> 8873.3047
A15: Total Revenue ($M) | B15: =B10+B14 -> 15425.836 | C15: =C10+C14 -> 14784.234 | D15: =D10+D14 -> 14171.048 | E15: =E10+E14 -> 13584.94 | F15: =F10+F14 -> 13024.64
A16: EBIT ($M) | B16: =B10*Cover_Assumptions!$B$18+B14*Cover_Assumptions!$B$19 -> 3062.6487 | C16: =C10*Cover_Assumptions!$B$18+C14*Cover_Assumptions!$B$19 -> 2953.8337 | D16: =D10*Cover_Assumptions!$B$18+D14*Cover_Assumptions!$B$19 -> 2848.9825 | E16: =E10*Cover_Assumptions!$B$18+E14*Cover_Assumptions!$B$19 -> 2747.9454 | F16: =F10*Cover_Assumptions!$B$18+F14*Cover_Assumptions!$B$19 -> 2650.5787
A18: Invest Case
B19: FY27 | C19: FY28 | D19: FY29 | E19: FY30 | F19: FY31
A20: Hardware Units (index) | B20: =B6/(1+Cover_Assumptions!$B$14) -> 100 | C20: =C6/(1+Cover_Assumptions!$B$14) -> 95.8 | D20: =D6/(1+Cover_Assumptions!$B$14) -> 91.7764 | E20: =E6/(1+Cover_Assumptions!$B$14) -> 87.921791 | F20: =F6/(1+Cover_Assumptions!$B$14) -> 84.229076
A21: Hardware ASP (index) | B21: =B7/(1+Cover_Assumptions!$B$15) -> 100 | C21: =C7/(1+Cover_Assumptions!$B$15) -> 98.5 | D21: =D7/(1+Cover_Assumptions!$B$15) -> 97.0225 | E21: =E7/(1+Cover_Assumptions!$B$15) -> 95.567162 | F21: =F7/(1+Cover_Assumptions!$B$15) -> 94.133655
A22: Hardware Revenue (index) | B22: =B20*B21/100 -> 100 | C22: =C20*C21/100 -> 94.363 | D22: =D20*D21/100 -> 89.043758 | E22: =E20*E21/100 -> 84.024361 | F22: =F20*F21/100 -> 79.287908
A24: Hardware Revenue ($M) | B24: =Cover_Assumptions!$B$27*1000*(1+Cover_Assumptions!$B$14)*(1+Cover_Assumptions!$B$15)*(B22/100) -> 5548.5444 | C24: =Cover_Assumptions!$B$27*1000*(1+Cover_Assumptions!$B$14)*(1+Cover_Assumptions!$B$15)*(C22/100) -> 5235.773 | D24: =Cover_Assumptions!$B$27*1000*(1+Cover_Assumptions!$B$14)*(1+Cover_Assumptions!$B$15)*(D22/100) -> 4940.6324 | E24: =Cover_Assumptions!$B$27*1000*(1+Cover_Assumptions!$B$14)*(1+Cover_Assumptions!$B$15)*(E22/100) -> 4662.129 | F24: =Cover_Assumptions!$B$27*1000*(1+Cover_Assumptions!$B$14)*(1+Cover_Assumptions!$B$15)*(F22/100) -> 4399.3248
A26: Supplies Capture Rate (index) | B26: =B12+($C$2*100) -> 100.1 | C26: =C12+($C$2*100) -> 96.8156 | D26: =D12+($C$2*100) -> 93.64287 | E26: =E12+($C$2*100) -> 90.578012 | F26: =F12+($C$2*100) -> 87.61736
A28: Supplies Revenue ($M) | B28: =(Cover_Assumptions!$B$11*1000-Cover_Assumptions!$B$27*1000)*(1+Cover_Assumptions!$B$13)*(B26/100) -> 10559.269 | C28: =(Cover_Assumptions!$B$11*1000-Cover_Assumptions!$B$27*1000)*(1+Cover_Assumptions!$B$13)*(C26/100) -> 10212.807 | D28: =(Cover_Assumptions!$B$11*1000-Cover_Assumptions!$B$27*1000)*(1+Cover_Assumptions!$B$13)*(D26/100) -> 9878.1241 | E28: =(Cover_Assumptions!$B$11*1000-Cover_Assumptions!$B$27*1000)*(1+Cover_Assumptions!$B$13)*(E26/100) -> 9554.8209 | F28: =(Cover_Assumptions!$B$11*1000-Cover_Assumptions!$B$27*1000)*(1+Cover_Assumptions!$B$13)*(F26/100) -> 9242.5099
A29: Total Revenue ($M) | B29: =B24+B28 -> 16107.813 | C29: =C24+C28 -> 15448.58 | D29: =D24+D28 -> 14818.757 | E29: =E24+E28 -> 14216.95 | F29: =F24+F28 -> 13641.835
A30: EBIT ($M) | B30: =B24*Cover_Assumptions!$B$18+B28*Cover_Assumptions!$B$19 -> 3178.537 | C30: =C24*Cover_Assumptions!$B$18+C28*Cover_Assumptions!$B$19 -> 3069.0168 | D30: =D24*Cover_Assumptions!$B$18+D28*Cover_Assumptions!$B$19 -> 2963.5 | E30: =E24*Cover_Assumptions!$B$18+E28*Cover_Assumptions!$B$19 -> 2861.835 | F30: =F24*Cover_Assumptions!$B$18+F28*Cover_Assumptions!$B$19 -> 2763.8758
A31: NPI Launch Cost ($M) | B31: =-$C$3 -> -200 | C31: 0 | D31: 0 | E31: 0 | F31: 0
A33: Invest Case Net Cash Flow ($M) | B33: =B30+B31 -> 2978.537 | C33: =C30+C31 -> 3069.0168 | D33: =D30+D31 -> 2963.5 | E33: =E30+E31 -> 2861.835 | F33: =F30+F31 -> 2763.8758
A35: NPV Calculation
B36: FY27 | C36: FY28 | D36: FY29 | E36: FY30 | F36: FY31
A37: Incremental Cash Flow ($M) | B37: =B33-B16 -> -84.111686 | C37: =C33-C16 -> 115.18308 | D37: =D33-D16 -> 114.51759 | E37: =E33-E16 -> 113.88962 | F37: =F33-F16 -> 113.29705
A39: Discount Factor | B39: =1/(1+Cover_Assumptions!$B$4)^(COLUMN()-COLUMN($B$5)+1) -> 0.92592593 | C39: =1/(1+Cover_Assumptions!$B$4)^(COLUMN()-COLUMN($B$5)+1) -> 0.85733882 | D39: =1/(1+Cover_Assumptions!$B$4)^(COLUMN()-COLUMN($B$5)+1) -> 0.79383224 | E39: =1/(1+Cover_Assumptions!$B$4)^(COLUMN()-COLUMN($B$5)+1) -> 0.73502985 | F39: =1/(1+Cover_Assumptions!$B$4)^(COLUMN()-COLUMN($B$5)+1) -> 0.6805832
A41: PV of Incremental CF ($M) | B41: =B37*B39 -> -77.881191 | C41: =C37*C39 -> 98.750923 | D41: =D37*D39 -> 90.907758 | E41: =E37*E39 -> 83.712274 | F41: =F37*F39 -> 77.108071
A43: NPV ($M) | B43: =SUM(B41:F41) -> 272.59784
A46: Sensitivity Analysis - Recapture Premium (%) x NPI Cost ($M)
A47: Recapture Sensitivity ($M NPV per 1.0pt) | B47: =Cover_Assumptions!$B$19*((Cover_Assumptions!$B$11*1000-Cover_Assumptions!$B$27*1000)*(1+Cover_Assumptions!$B$13))/100*SUM(B39:F39) -> 117.93034
A48: NPI Cost Sensitivity ($M NPV per $1M) | B48: =-B39 -> -0.92592593
A49: Base/Base NPV Reference (fixed snapshot, for grid intercept only) | B49: 272.6
A50: Intercept (from Base/Base NPV Reference) | B50: =$B$49-$B$47*3.5-$B$48*200 -> 45.028979 | C50: Derived from B47, B48, and the fixed B49 reference — deliberately independent of the live scenario toggles, so the grid stays correct regardless of toggle position.
B52: 150 | C52: =B52+10 -> 160 | D52: =C52+10 -> 170 | E52: =D52+10 -> 180 | F52: =E52+10 -> 190 | G52: =F52+10 -> 200 | H52: =G52+10 -> 210 | I52: =H52+10 -> 220 | J52: =I52+10 -> 230 | ... Q52: =P52+10 -> 300
A53: 0.015 | B53: =$B$50+$B$47*$A53*100+B$52*$B$48 -> 83.035607 | C53: =$B$50+$B$47*$A53*100+C$52*$B$48 -> 73.776348 | D53: =$B$50+$B$47*$A53*100+D$52*$B$48 -> 64.517089 | E53: =$B$50+$B$47*$A53*100+E$52*$B$48 -> 55.257829 | F53: =$B$50+$B$47*$A53*100+F$52*$B$48 -> 45.99857 | G53: =$B$50+$B$47*$A53*100+G$52*$B$48 -> 36.739311 | H53: =$B$50+$B$47*$A53*100+H$52*$B$48 -> 27.480051 | I53: =$B$50+$B$47*$A53*100+I$52*$B$48 -> 18.220792 | ... Q53: =$B$50+$B$47*$A53*100+Q$52*$B$48 -> -55.853282
A54: =A53+1/300 -> 0.018333333 | B54: =$B$50+$B$47*$A54*100+B$52*$B$48 -> 122.34572 | C54: =$B$50+$B$47*$A54*100+C$52*$B$48 -> 113.08646 | D54: =$B$50+$B$47*$A54*100+D$52*$B$48 -> 103.8272 | E54: =$B$50+$B$47*$A54*100+E$52*$B$48 -> 94.567944 | F54: =$B$50+$B$47*$A54*100+F$52*$B$48 -> 85.308685 | G54: =$B$50+$B$47*$A54*100+G$52*$B$48 -> 76.049426 | H54: =$B$50+$B$47*$A54*100+H$52*$B$48 -> 66.790166 | I54: =$B$50+$B$47*$A54*100+I$52*$B$48 -> 57.530907 | ... Q54: =$B$50+$B$47*$A54*100+Q$52*$B$48 -> -16.543167
A55: =A54+1/300 -> 0.021666667 | B55: =$B$50+$B$47*$A55*100+B$52*$B$48 -> 161.65584 | C55: =$B$50+$B$47*$A55*100+C$52*$B$48 -> 152.39658 | D55: =$B$50+$B$47*$A55*100+D$52*$B$48 -> 143.13732 | E55: =$B$50+$B$47*$A55*100+E$52*$B$48 -> 133.87806 | F55: =$B$50+$B$47*$A55*100+F$52*$B$48 -> 124.6188 | G55: =$B$50+$B$47*$A55*100+G$52*$B$48 -> 115.35954 | H55: =$B$50+$B$47*$A55*100+H$52*$B$48 -> 106.10028 | I55: =$B$50+$B$47*$A55*100+I$52*$B$48 -> 96.841022 | ... Q55: =$B$50+$B$47*$A55*100+Q$52*$B$48 -> 22.766948
...

Sheet Option_B
A1: Option B - Instant Ink Subscription Acceleration
A2: CAC Scenario: | B2: Base | C2: =CHOOSE(MATCH($B$2,{"Lean","Base","Ambitious"},0),Cover_Assumptions!$B$33,Cover_Assumptions!$B$34,Cover_Assumptions!$B$35) -> 40
A3: Growth Acceleration Scenario: | B3: Base | C3: =CHOOSE(MATCH($B$3,{"Downside","Base","Upside"},0),Cover_Assumptions!$B$36,Cover_Assumptions!$B$37,Cover_Assumptions!$B$38) -> 0.04
A4: Do-Nothing Case
B5: FY27 | C5: FY28 | D5: FY29 | E5: FY30 | F5: FY31
A6: Subscription Revenue Index (FY26=100) | B6: =100*(1+Cover_Assumptions!$B$32) -> 107 | C6: =B6*(1+Cover_Assumptions!$B$32) -> 114.49 | D6: =C6*(1+Cover_Assumptions!$B$32) -> 122.5043 | E6: =D6*(1+Cover_Assumptions!$B$32) -> 131.0796 | F6: =E6*(1+Cover_Assumptions!$B$32) -> 140.25517
A8: Subscription Revenue ($M) | B8: =(Cover_Assumptions!$B$11*1000-Cover_Assumptions!$B$27*1000)*Cover_Assumptions!$B$39*(1+Cover_Assumptions!$B$32)*(B6/100) -> 1250.2308 | C8: =(Cover_Assumptions!$B$11*1000-Cover_Assumptions!$B$27*1000)*Cover_Assumptions!$B$39*(1+Cover_Assumptions!$B$32)*(C6/100) -> 1337.747 | D8: =(Cover_Assumptions!$B$11*1000-Cover_Assumptions!$B$27*1000)*Cover_Assumptions!$B$39*(1+Cover_Assumptions!$B$32)*(D6/100) -> 1431.3892 | E8: =(Cover_Assumptions!$B$11*1000-Cover_Assumptions!$B$27*1000)*Cover_Assumptions!$B$39*(1+Cover_Assumptions!$B$32)*(E6/100) -> 1531.5865 | F8: =(Cover_Assumptions!$B$11*1000-Cover_Assumptions!$B$27*1000)*Cover_Assumptions!$B$39*(1+Cover_Assumptions!$B$32)*(F6/100) -> 1638.7975
A10: Non-Subscription Revenue Index (FY26=100) | B10: =100*(1+Cover_Assumptions!$B$40) -> 95.444444 | C10: =B10*(1+Cover_Assumptions!$B$40) -> 91.09642 | D10: =C10*(1+Cover_Assumptions!$B$40) -> 86.946472 | E10: =D10*(1+Cover_Assumptions!$B$40) -> 82.985577 | F10: =E10*(1+Cover_Assumptions!$B$40) -> 79.205123
A12: Non-Subscription Revenue ($M) | B12: =(Cover_Assumptions!$B$11*1000-Cover_Assumptions!$B$27*1000)*(1-Cover_Assumptions!$B$39)*(1+Cover_Assumptions!$B$40)*(B10/100) -> 8952.9561 | C12: =(Cover_Assumptions!$B$11*1000-Cover_Assumptions!$B$27*1000)*(1-Cover_Assumptions!$B$39)*(1+Cover_Assumptions!$B$40)*(C10/100) -> 8545.0992 | D12: =(Cover_Assumptions!$B$11*1000-Cover_Assumptions!$B$27*1000)*(1-Cover_Assumptions!$B$39)*(1+Cover_Assumptions!$B$40)*(D10/100) -> 8155.8225 | E12: =(Cover_Assumptions!$B$11*1000-Cover_Assumptions!$B$27*1000)*(1-Cover_Assumptions!$B$39)*(1+Cover_Assumptions!$B$40)*(E10/100) -> 7784.2795 | F12: =(Cover_Assumptions!$B$11*1000-Cover_Assumptions!$B$27*1000)*(1-Cover_Assumptions!$B$39)*(1+Cover_Assumptions!$B$40)*(F10/100) -> 7429.6623
A14: Total Supplies Revenue ($M) | B14: =B8+B12 -> 10203.187 | C14: =C8+C12 -> 9882.8462 | D14: =D8+D12 -> 9587.2117 | E14: =E8+E12 -> 9315.866 | F14: =F8+F12 -> 9068.4598
A16: EBIT ($M) | B16: =B14*Cover_Assumptions!$B$19 -> 2856.8923 | C16: =C14*Cover_Assumptions!$B$19 -> 2767.1969 | D16: =D14*Cover_Assumptions!$B$19 -> 2684.4193 | E16: =E14*Cover_Assumptions!$B$19 -> 2608.4425 | F16: =F14*Cover_Assumptions!$B$19 -> 2539.1688
A18: Invest Case
B19: FY27 | C19: FY28 | D19: FY29 | E19: FY30 | F19: FY31
A20: Subscription Revenue Index - Invest Case (accelarated growth) | B20: =100*(1+Cover_Assumptions!$B$32+$C$3) -> 111 | C20: =B20*(1+Cover_Assumptions!$B$32+$C$3) -> 123.21 | D20: =C20*(1+Cover_Assumptions!$B$32+$C$3) -> 136.7631 | E20: =D20*(1+Cover_Assumptions!$B$32+$C$3) -> 151.80704 | F20: =E20*(1+Cover_Assumptions!$B$32+$C$3) -> 168.50582
A22: Subscription Revenue ($M), Invest Case | B22: =(Cover_Assumptions!$B$11*1000-Cover_Assumptions!$B$27*1000)*Cover_Assumptions!$B$39*(1+Cover_Assumptions!$B$32)*(B20/100) -> 1296.9684 | C22: =(Cover_Assumptions!$B$11*1000-Cover_Assumptions!$B$27*1000)*Cover_Assumptions!$B$39*(1+Cover_Assumptions!$B$32)*(C20/100) -> 1439.6349 | D22: =(Cover_Assumptions!$B$11*1000-Cover_Assumptions!$B$27*1000)*Cover_Assumptions!$B$39*(1+Cover_Assumptions!$B$32)*(D20/100) -> 1597.9948 | E22: =(Cover_Assumptions!$B$11*1000-Cover_Assumptions!$B$27*1000)*Cover_Assumptions!$B$39*(1+Cover_Assumptions!$B$32)*(E20/100) -> 1773.7742 | F22: =(Cover_Assumptions!$B$11*1000-Cover_Assumptions!$B$27*1000)*Cover_Assumptions!$B$39*(1+Cover_Assumptions!$B$32)*(F20/100) -> 1968.8894
A24: Do-Nothing Subscriber Count (millions) | B24: =Cover_Assumptions!$B$41*(B6/100) -> 15.925559 | C24: =Cover_Assumptions!$B$41*(C6/100) -> 17.040348 | D24: =Cover_Assumptions!$B$41*(D6/100) -> 18.233172 | E24: =Cover_Assumptions!$B$41*(E6/100) -> 19.509495 | F24: =Cover_Assumptions!$B$41*(F6/100) -> 20.875159
A26: Invest Case Subscriber Count (millions) | B26: =Cover_Assumptions!$B$41*(B20/100) -> 16.520907 | C26: =Cover_Assumptions!$B$41*(C20/100) -> 18.338207 | D26: =Cover_Assumptions!$B$41*(D20/100) -> 20.35541 | E26: =Cover_Assumptions!$B$41*(E20/100) -> 22.594505 | F26: =Cover_Assumptions!$B$41*(F20/100) -> 25.0799
A28: Incremental Subscriber Count (millions) | B28: =B26-B24 -> 0.595348 | C28: =C26-C24 -> 1.2978586 | D28: =D26-D24 -> 2.122237 | E28: =E26-E24 -> 3.08501 | F28: =F26-F24 -> 4.2047409
A30: Year-over-Year New Incremental Subscribers (millions) | B30: =B28 -> 0.595348 | C30: =C28-B28 -> 0.70251064 | D30: =D28-C28 -> 0.82437838 | E30: =E28-D28 -> 0.96277297 | F30: =F28-E28 -> 1.1197309
A32: CAC Cost ($M) | B32: =-B30*$C$2 -> -23.81392 | C32: =-C30*$C$2 -> -28.100426 | D32: =-D30*$C$2 -> -32.975135 | E32: =-E30*$C$2 -> -38.510919 | F32: =-F30*$C$2 -> -44.789235
A36: Non-Subscription Revenue, Invest Case ($M) | B36: =B12 -> 8952.9561 | C36: =C12 -> 8545.0992 | D36: =D12 -> 8155.8225 | E36: =E12 -> 7784.2795 | F36: =F12 -> 7429.6623
A38: Total Supplies Revenue, Invest Case ($M) | B38: =B22+B36 -> 10249.925 | C38: =C22+C36 -> 9984.7342 | D38: =D22+D36 -> 9753.8173 | E38: =E22+E36 -> 9558.0537 | F38: =F22+F36 -> 9398.5516
A40: EBIT, Invest Case ($M) | B40: =B38*Cover_Assumptions!$B$19 -> 2869.9789 | C40: =C38*Cover_Assumptions!$B$19 -> 2795.7256 | D40: =D38*Cover_Assumptions!$B$19 -> 2731.0688 | E40: =E38*Cover_Assumptions!$B$19 -> 2676.255 | F40: =F38*Cover_Assumptions!$B$19 -> 2631.5945
A42: Invest Case Net Cash Flow ($M) | B42: =B40+B32 -> 2846.1649 | C42: =C40+C32 -> 2767.6251 | D42: =D40+D32 -> 2698.0937 | E42: =E40+E32 -> 2637.7441 | F42: =F40+F32 -> 2586.8052
A44: NPV Calculation
B45: FY27 | C45: FY28 | D45: FY29 | E45: FY30 | F45: FY31
A46: Incremental Cash Flow ($M) | B46: =B42-B16 -> -10.727392 | C46: =C42-C16 -> 0.42820544 | D46: =D42-D16 -> 13.674411 | E46: =E42-E16 -> 29.301637 | F46: =F42-F16 -> 47.636471
A48: Discount Factor | B48: =1/(1+Cover_Assumptions!$B$4)^(COLUMN()-COLUMN($B$5)+1) -> 0.92592593 | C48: =1/(1+Cover_Assumptions!$B$4)^(COLUMN()-COLUMN($B$5)+1) -> 0.85733882 | D48: =1/(1+Cover_Assumptions!$B$4)^(COLUMN()-COLUMN($B$5)+1) -> 0.79383224 | E48: =1/(1+Cover_Assumptions!$B$4)^(COLUMN()-COLUMN($B$5)+1) -> 0.73502985 | F48: =1/(1+Cover_Assumptions!$B$4)^(COLUMN()-COLUMN($B$5)+1) -> 0.6805832
A50: PV of Incremental CF ($M) | B50: =B46*B48 -> -9.9327704 | C50: =C46*C48 -> 0.36711715 | D50: =D46*D48 -> 10.855189 | E50: =E46*E48 -> 21.537578 | F50: =F46*F48 -> 32.420581
A52: NPV ($M) | B52: =SUM(B50:F50) -> 55.247695
A55: Sensitivity Analysis — Growth Acceleration × CAC per Subscriber
A56: =B52 -> 55.247695 | B56: 20 | C56: =B56+(60-20)/6 -> 26.666667 | D56: =C56+(60-20)/6 -> 33.333333 | E56: =D56+(60-20)/6 -> 40 | F56: =E56+(60-20)/6 -> 46.666667 | G56: =F56+(60-20)/6 -> 53.333333 | H56: =G56+(60-20)/6 -> 60
A57: 0.02 | B57: 59.23583 | C57: 48.685621 | D57: 38.135411 | E57: 27.585202 | F57: 17.034992 | G57: 6.484783 | H57: -4.0654264
A58: 0.03 | B58: 89.723069 | C58: 73.618686 | D58: 57.514303 | E58: 41.409921 | F58: 25.305538 | G58: 9.2011556 | H58: -6.9032271
A59: 0.04 | B59: 120.80155 | C59: 98.950266 | D59: 77.09898 | E59: 55.247695 | F59: 33.396409 | G59: 11.545124 | H59: -10.306162
A60: 0.05 | B60: 152.48015 | C60: 124.68411 | D60: 96.888061 | E60: 69.092018 | F60: 41.295974 | G60: 13.49993 | H60: -14.296114
A61: 0.06 | B61: 184.76781 | C61: 150.82394 | D61: 116.88006 | E61: 82.93619 | F61: 48.992315 | G61: 15.048441 | H61: -18.895433
A62: 0.07 | B62: 217.67358 | C62: 177.37349 | D62: 137.0734 | E62: 96.773317 | F62: 56.47323 | G62: 16.173143 | H62: -24.126943
A63: 0.08 | B63: 251.20655 | C63: 204.33647 | D63: 157.46639 | E63: 110.59631 | F63: 63.726224 | G63: 16.856142 | H63: -30.013941

Sheet Combined_Scenario
A1: Combined Scenario — Integrated Hardware + Subscription Strategy
A4: New-Generation Attach Effect
B5: FY27 | C5: FY28 | D5: FY29 | E5: FY30 | F5: FY31
A6: Incremental Hardware Revenue ($M), from Option A | B6: =Option_A!B24-Option_A!B10 -> 312.77145 | C6: =Option_A!C24-Option_A!C10 -> 295.14052 | D6: =Option_A!D24-Option_A!D10 -> 278.50345 | E6: =Option_A!E24-Option_A!E10 -> 262.80421 | F6: =Option_A!F24-Option_A!F10 -> 247.98994
A8: Attach Revenue ($M) | B8: =B6*Cover_Assumptions!$B$45 -> 46.915717 | C8: =C6*Cover_Assumptions!$B$45 -> 44.271078 | D8: =D6*Cover_Assumptions!$B$45 -> 41.775518 | E8: =E6*Cover_Assumptions!$B$45 -> 39.420632 | F8: =F6*Cover_Assumptions!$B$45 -> 37.198491
A10: Attach EBIT ($M) | B10: =B8*Cover_Assumptions!$B$19 -> 13.136401 | C10: =C8*Cover_Assumptions!$B$19 -> 12.395902 | D10: =D8*Cover_Assumptions!$B$19 -> 11.697145 | E10: =E8*Cover_Assumptions!$B$19 -> 11.037777 | F10: =F8*Cover_Assumptions!$B$19 -> 10.415577
A12: Discount Factor | B12: =1/(1+Cover_Assumptions!$B$4)^(COLUMN()-COLUMN($B$5)+1) -> 0.92592593 | C12: =1/(1+Cover_Assumptions!$B$4)^(COLUMN()-COLUMN($B$5)+1) -> 0.85733882 | D12: =1/(1+Cover_Assumptions!$B$4)^(COLUMN()-COLUMN($B$5)+1) -> 0.79383224 | E12: =1/(1+Cover_Assumptions!$B$4)^(COLUMN()-COLUMN($B$5)+1) -> 0.73502985 | F12: =1/(1+Cover_Assumptions!$B$4)^(COLUMN()-COLUMN($B$5)+1) -> 0.6805832
A14: PV of Attach EBIT ($M) | B14: =B10*B12 -> 12.163334 | C14: =C10*C12 -> 10.627488 | D14: =D10*D12 -> 9.2855708 | E14: =E10*E12 -> 8.1130955 | F14: =F10*F12 -> 7.0886669
A16: Attach Effect NPV ($M) | B16: =SUM(B14:F14) -> 47.278155
A19: Total Combined Scenario NPV
A20: Total Combined Scenario NPV ($M) | B20: =Option_A!$B$43+Option_B!$B$52+B16 -> 375.12369
A22: Note: this total is a simple sum of independently-verified components, not a fully-integrated model — it does not net out potential overlap between Option A's hardware-driven attach and Option B's targeted marketing reaching some of the same eventual converts. Shown as a directional "what funding all three efforts together could plausibly deliver" figure, not a precision estimate.

Sheet Portfolio_Comparison
A1: Portfolio Comparison — HP Print Franchise Options
A4: Financial Summary
B6: Worst Case | C6: Base Case | D6: Best Case
A7: Option A - New Printer Generation Launch | B7: -55.9 | C7: 272.6 | D7: 672.7
A8: Option B - Instant Ink Subscription Acceleration | B8: -4.1 | C8: 55.2 | D8: 251.2
A9: Combined Scenario (A + B + Attach Effect) | C9: 375.1
A10: Note: Fixed reference values sourced from Option_A!/Option_B!/Combined_Scenario!'s verified NPV cells — typed, not live-linked, to keep this summary stable regardless of toggle position on the option tabs.
A11: ⚠ SCOPE LIMITATION: Option A's economics are presented at full Printing-segment scale (all product lines, all generations, consumer and commercial combined). A real single-generation launch decision represents some fraction of this that HP does not publicly disclose and this model does not estimate. Figures here should be read as a ceiling case for a segment-wide refresh posture, not the literal economics of one product launch. Option B is scoped to the global consumer/home segment specifically.
A13: Market Attractiveness
A14: Criterion | B14: Option A Rating | C14: Option A Rationale | D14: Option B Rating | E14: Option B Rationale
A15: Opportunity size | B15: High | C15: Touches the entire $16.8B Printing segment revenue base (hardware + all supplies) | D15: Med | E15: Targets the subscription slice of the Supplies base — modeled at ~10% in this project (Cover_Assumptions row 38), an internally triangulated estimate, not an HP-disclosed figure
A16: Growth trajectory | B16: Low | C16: Segment revenue declining ~3–4%/yr per FY25 10-K; no organic tailwind | D16: High | E16: Real disclosed subscriber growth (~7–9%/yr organic, per HP management commentary), positive momentum against an otherwise-declining segment
A17: Competitive intensity | B17: Med | C17: Generic/compatible cartridge and big-tank competition, named directly in HP's own 10-K | D17: Low-Med | E17: Subscription-model competition exists but is less commoditized than cartridge price competition
A18: Structural durability | B18: Low | C18: Aftermarket edge fades again as the newly-launched fleet itself ages toward the same decay curve — the benefit resets rather than compounds, eroding on a schedule regardless of launch execution | D18: High | E18: Conversion opportunity doesn't decay on a comparable schedule; a 2020 HP investor filing showed >90% retention among Instant Ink subscribers (dated data, FY16–19, but a real directional signal of durability once converted)
A20: Right-to-Win
A21: Criterion | B21: Option A Rating | C21: Option A Rationale | D21: Option B Rating | E21: Option B Rationale
A22: Fit with existing capabilities | B22: High | C22: HP has an established, repeatable NPI/hardware-launch capability | D22: High | E22: Instant Ink billing/subscription infrastructure already operating at scale (13M+ subscribers)
A23: Execution complexity | B23: Med | C23: Large program (R&D, tooling, launch) but a well-trodden internal process | D23: Low | E23: Marketing push, no new hardware or manufacturing required
A24: Time-to-impact | B24: Med | C24: NPI cycles require real planning/shipping time before any benefit is realized | D24: High | E24: A marketing campaign can launch quickly, no multi-year cycle required
A25: Cannibalization/channel risk | B25: Low | C25: Standard refresh cycle, expected replacement, not an unusual cannibalization risk | D25: Med-High | E25: Converting a transactional buyer reduces near-term one-off cartridge revenue — and critically, the customers most attractive to target (high-usage, high-loyalty transactional buyers) are also the customers most valuable to Instant Ink, meaning the best acquisition targets are also the highest-value transactional revenue being given up
A28: Sequencing Recommendation
A29: Fund both options, coordinated rather than run independently. Option A carries the larger base-case opportunity (~5x Option B's) but a genuinely negative worst case, and its aftermarket edge decays on its own clock as the refreshed fleet ages, resetting rather than compounding. Option B offers a materially safer downside and durable, non-decaying value once converted, but a smaller absolute ceiling on its own. The stronger finding, though, isn't which one to prioritize — it's that designing the subscription push to run in tandem with the hardware launch, rather than as a disconnected campaign, captures real additional value (~$47.3M in this model) that neither option delivers funded alone. The recommendation is to fund both, with Option B's marketing/enrollment strategy deliberately built around Option A's launch timeline rather than scheduled independently.
A31: Alternatives Considered, Not Modeled
A32: Instant Ink-only printer SKU | B32: A subscription-only hardware form factor was one of several concepts explored in HP's product strategy discussions during my tenure. Not modeled in this project.
A33: Ink tank printer launch in developed markets | B33: Cannibalization risk against the traditional cartridge model was a live strategic question at HP. Could function as either an alternative or complementary lever to Options A/B; not modeled in this project.
